<sdf version='1.6'>
  <world name='default'>
    <light name='sun' type='directional'>
      <cast_shadows>1</cast_shadows>
      <pose frame=''>0 0 10 0 -0 0</pose>
      <diffuse>0.8 0.8 0.8 1</diffuse>
      <specular>0.2 0.2 0.2 1</specular>
      <attenuation>
        <range>1000</range>
        <constant>0.9</constant>
        <linear>0.01</linear>
        <quadratic>0.001</quadratic>
      </attenuation>
      <direction>-0.5 0.1 -0.9</direction>
    </light>
    <model name='ground_plane'>
      <static>1</static>
      <link name='link'>
        <collision name='collision'>
          <geometry>
            <plane>
              <normal>0 0 1</normal>
              <size>100 100</size>
            </plane>
          </geometry>
          <surface>
            <friction>
              <ode>
                <mu>100</mu>
                <mu2>50</mu2>
              </ode>
              <torsional>
                <ode/>
              </torsional>
            </friction>
            <contact>
              <ode/>
            </contact>
            <bounce/>
          </surface>
          <max_contacts>10</max_contacts>
        </collision>
        <visual name='visual'>
          <cast_shadows>0</cast_shadows>
          <geometry>
            <plane>
              <normal>0 0 1</normal>
              <size>100 100</size>
            </plane>
          </geometry>
          <material>
            <script>
              <uri>file://media/materials/scripts/gazebo.material</uri>
              <name>Gazebo/Grey</name>
            </script>
          </material>
        </visual>
        <self_collide>0</self_collide>
        <enable_wind>0</enable_wind>
        <kinematic>0</kinematic>
      </link>
    </model>
    <gravity>0 0 -9.8</gravity>
    <magnetic_field>6e-06 2.3e-05 -4.2e-05</magnetic_field>
    <atmosphere type='adiabatic'/>
    <physics name='default_physics' default='0' type='ode'>
      <max_step_size>0.001</max_step_size>
      <real_time_factor>1</real_time_factor>
      <real_time_update_rate>400</real_time_update_rate>
    </physics>
    <scene>
      <ambient>0.4 0.4 0.4 1</ambient>
      <background>0.7 0.7 0.7 1</background>
      <shadows>1</shadows>
    </scene>
    <wind/>
    <spherical_coordinates>
      <surface_model>EARTH_WGS84</surface_model>
      <latitude_deg>0</latitude_deg>
      <longitude_deg>0</longitude_deg>
      <elevation>0</elevation>
      <heading_deg>0</heading_deg>
    </spherical_coordinates>
    <state world_name='default'>
      <sim_time>1650 243000000</sim_time>
      <real_time>161 551424172</real_time>
      <wall_time>1601368186 760179229</wall_time>
      <iterations>64305</iterations>
      <model name='drone_with_box'>
        <pose frame=''>0.549307 3.51078 0 0 -0 0</pose>
        <scale>1 1 1</scale>
        <link name='box_link'>
          <pose frame=''>0.549307 3.51078 0 0 -0 0</pose>
          <velocity>0 0 0 0 -0 0</velocity>
          <acceleration>0 0 0 0 -0 0</acceleration>
          <wrench>0 0 0 0 -0 0</wrench>
        </link>
        <link name='drone::link'>
          <pose frame=''>0.549307 3.51078 0 0 0 -1.5707</pose>
          <velocity>0 0 0 0 -0 0</velocity>
          <acceleration>0 0 0 0 -0 0</acceleration>
          <wrench>0 0 0 0 -0 0</wrench>
        </link>
      </model>
      <model name='drone_with_box_clone'>
        <pose frame=''>0.58877 -5.93038 0 0 -0 0</pose>
        <scale>1 1 1</scale>
        <link name='box_link'>
          <pose frame=''>0.58877 -5.93038 0 0 -0 0</pose>
          <velocity>0 0 0 0 -0 0</velocity>
          <acceleration>0 0 0 0 -0 0</acceleration>
          <wrench>0 0 0 0 -0 0</wrench>
        </link>
        <link name='drone::link'>
          <pose frame=''>0.58877 -5.93038 0 0 0 -1.5707</pose>
          <velocity>0 0 0 0 -0 0</velocity>
          <acceleration>0 0 0 0 -0 0</acceleration>
          <wrench>0 0 0 0 -0 0</wrench>
        </link>
      </model>
      <model name='ground_plane'>
        <pose frame=''>0 0 0 0 -0 0</pose>
        <scale>1 1 1</scale>
        <link name='link'>
          <pose frame=''>0 0 0 0 -0 0</pose>
          <velocity>0 0 0 0 -0 0</velocity>
          <acceleration>0 0 0 0 -0 0</acceleration>
          <wrench>0 0 0 0 -0 0</wrench>
        </link>
      </model>
      <model name='lrmate200id7l'>
        <pose frame=''>-0 0 0 0 -0 0</pose>
        <scale>1 1 1</scale>
        <link name='base_link'>
          <pose frame=''>-0 0 0 0 -0 0</pose>
          <velocity>-0 1e-06 -0 1.6e-05 6e-06 0</velocity>
          <acceleration>-0.001961 0.001923 -0.003131 -0.02205 -0.014281 -0.005539</acceleration>
          <wrench>-0.021047 0.020639 -0.033601 0 -0 0</wrench>
        </link>
        <link name='link_1'>
          <pose frame=''>0 -0 0.33 0 1e-06 -0.000303</pose>
          <velocity>3e-06 -7e-06 0 3.9e-05 1.5e-05 -1.7e-05</velocity>
          <acceleration>-0.005088 0.00795 -0.001781 0.009364 -0.033541 -0.003226</acceleration>
          <wrench>-0.086167 0.134636 -0.030161 0 -0 0</wrench>
        </link>
        <link name='link_2'>
          <pose frame=''>0.05 -1.5e-05 0.33 0 -0.426978 -0.000303</pose>
          <velocity>3e-06 -8e-06 0 4.1e-05 -1.7e-05 -1.8e-05</velocity>
          <acceleration>-0.002595 0.001995 0.009089 0.059186 -0.002292 -0.073603</acceleration>
          <wrench>-0.033701 0.025915 0.11804 0 -0 0</wrench>
        </link>
        <link name='link_3'>
          <pose frame=''>-0.132214 4e-05 0.730497 0 -0.292189 -0.000303</pose>
          <velocity>-4e-06 -2.1e-05 -3e-06 4.2e-05 5e-06 -1.9e-05</velocity>
          <acceleration>-0.003216 -0.004976 0.004643 0.032903 -0.002847 -0.0201</acceleration>
          <wrench>-0.024125 -0.037325 0.034828 0 -0 0</wrench>
        </link>
        <link name='link_4'>
          <pose frame=''>-0.142295 4.3e-05 0.764014 0.000955 -0.292189 -0.000303</pose>
          <velocity>-3e-06 -2.3e-05 -3e-06 -4.9e-05 5e-06 -4.8e-05</velocity>
          <acceleration>-0.000689 -0.002045 0.002978 0.00295 -0.001895 -0.027876</acceleration>
          <wrench>-0.003127 -0.009287 0.01352 0 -0 0</wrench>
        </link>
        <link name='link_5'>
          <pose frame=''>0.259903 -7.9e-05 0.884994 1.38121 1.56987 1.38118</pose>
          <velocity>-2e-06 -4.5e-05 -5e-06 -4.8e-05 -3.2e-05 -4.7e-05</velocity>
          <acceleration>-0.001272 -0.073732 0.000154 0.014871 0.010662 -0.009653</acceleration>
          <wrench>-0.000723 -0.041936 8.7e-05 0 -0 0</wrench>
        </link>
        <link name='link_6'>
          <pose frame=''>0.259917 -6e-06 0.804995 1.38074 1.56987 1.38121</pose>
          <velocity>0 -4.9e-05 -5e-06 -5.1e-05 -3.2e-05 7e-06</velocity>
          <acceleration>-0.003872 -0.07173 0.00159 -0.021396 0.009572 0.007902</acceleration>
          <wrench>-0.000159 -0.002939 6.5e-05 0 -0 0</wrench>
        </link>
      </model>
      <model name='open_box'>
        <pose frame=''>0.355284 0.071616 -0.000776 -0.000425 0.000133 -0</pose>
        <scale>1 1 1</scale>
        <link name='box_base'>
          <pose frame=''>0.355284 0.071616 -0.000776 -0.000425 0.000133 -0</pose>
          <velocity>-0 0 -0 0 -0 0</velocity>
          <acceleration>-0 0 -0 0 -0 0</acceleration>
          <wrench>-0 0 -0 0 -0 0</wrench>
        </link>
      </model>
      <model name='visp_marker_100mm'>
        <pose frame=''>0.675063 0.015019 0.139294 -0.001605 1.56708 -3.14159</pose>
        <scale>1 1 1</scale>
        <link name='link'>
          <pose frame=''>0.675063 0.015019 0.139294 -0.001605 1.56708 -3.14159</pose>
          <velocity>0 0 0 0 -0 0</velocity>
          <acceleration>0 0 0 0 -0 0</acceleration>
          <wrench>0 0 0 0 -0 0</wrench>
        </link>
      </model>
      <light name='sun'>
        <pose frame=''>0 0 10 0 -0 0</pose>
      </light>
    </state>
    <gui fullscreen='0'>
      <camera name='user_camera'>
        <pose frame=''>2.08075 -5.0504 2.86911 0 0.4938 1.87286</pose>
        <view_controller>orbit</view_controller>
        <projection_type>perspective</projection_type>
      </camera>
    </gui>
    <plugin name='fanuc_lrmate200id_gazebo_pick_place' filename='libfanuc_lrmate200id_gazebo_pick_place.so'/>
    <audio>
      <device>default</device>
    </audio>
    <model name='open_box'>
      <static>0</static>
      <self_collide>0</self_collide>
      <link name='box_base'>
        <gravity>1</gravity>
        <inertial>
          <mass>1</mass>
          <inertia>
            <ixx>0.0408</ixx>
            <ixy>0</ixy>
            <ixz>0</ixz>
            <iyy>0.02084</iyy>
            <iyz>0</iyz>
            <izz>0.0616</izz>
          </inertia>
        </inertial>
        <sensor name='shipping_box_contact' type='contact'>
          <update_rate>1</update_rate>
          <contact>
            <collision>box_base</collision>
            <topic>__default_topic__</topic>
          </contact>
        </sensor>
        <collision name='box_base'>
          <pose frame=''>0 0 0.0015 0 -0 0</pose>
          <max_contacts>10</max_contacts>
          <surface>
            <contact>
              <ode>
                <max_vel>0</max_vel>
                <min_depth>0.001</min_depth>
              </ode>
            </contact>
            <bounce/>
            <friction>
              <torsional>
                <ode/>
              </torsional>
              <ode/>
            </friction>
          </surface>
          <geometry>
            <box>
              <size>0.49 0.69 0.001</size>
            </box>
          </geometry>
        </collision>
        <collision name='box_bottom'>
          <pose frame=''>0 0 0.0005 0 -0 0</pose>
          <max_contacts>10</max_contacts>
          <surface>
            <contact>
              <ode>
                <max_vel>0</max_vel>
                <min_depth>0.001</min_depth>
              </ode>
            </contact>
            <bounce/>
            <friction>
              <torsional>
                <ode/>
              </torsional>
              <ode/>
            </friction>
          </surface>
          <geometry>
            <box>
              <size>0.49 0.69 0.001</size>
            </box>
          </geometry>
        </collision>
        <collision name='tray_collision1'>
          <pose frame=''>0.25 0 0.0127 0 -0 0</pose>
          <max_contacts>10</max_contacts>
          <surface>
            <contact>
              <ode>
                <max_vel>0</max_vel>
                <min_depth>0.001</min_depth>
              </ode>
            </contact>
            <bounce/>
            <friction>
              <torsional>
                <ode/>
              </torsional>
              <ode/>
            </friction>
          </surface>
          <geometry>
            <box>
              <size>0.001 0.7 0.0254</size>
            </box>
          </geometry>
        </collision>
        <collision name='tray_collision2'>
          <pose frame=''>-0.25 0 0.0127 0 -0 0</pose>
          <max_contacts>10</max_contacts>
          <surface>
            <contact>
              <ode>
                <max_vel>0</max_vel>
                <min_depth>0.001</min_depth>
              </ode>
            </contact>
            <bounce/>
            <friction>
              <torsional>
                <ode/>
              </torsional>
              <ode/>
            </friction>
          </surface>
          <geometry>
            <box>
              <size>0.001 0.7 0.0254</size>
            </box>
          </geometry>
        </collision>
        <collision name='tray_collision3'>
          <pose frame=''>0 0.35 0.0127 0 -0 0</pose>
          <max_contacts>10</max_contacts>
          <surface>
            <contact>
              <ode>
                <max_vel>0</max_vel>
                <min_depth>0.001</min_depth>
              </ode>
            </contact>
            <bounce/>
            <friction>
              <torsional>
                <ode/>
              </torsional>
              <ode/>
            </friction>
          </surface>
          <geometry>
            <box>
              <size>0.5 0.001 0.0254</size>
            </box>
          </geometry>
        </collision>
        <collision name='tray_collision4'>
          <pose frame=''>0 -0.35 0.0127 0 -0 0</pose>
          <max_contacts>10</max_contacts>
          <surface>
            <contact>
              <ode>
                <max_vel>0</max_vel>
                <min_depth>0.001</min_depth>
              </ode>
            </contact>
            <bounce/>
            <friction>
              <torsional>
                <ode/>
              </torsional>
              <ode/>
            </friction>
          </surface>
          <geometry>
            <box>
              <size>0.5 0.001 0.0254</size>
            </box>
          </geometry>
        </collision>
        <visual name='open_box'>
          <geometry>
            <mesh>
              <scale>1.1 1.8 0.25</scale>
              <uri>model://open_box_ariac/meshes/open_box.obj</uri>
            </mesh>
          </geometry>
          <plugin name='toggle' filename='libToggleVisualPlugin.so'>
            <initially_visible>1</initially_visible>
            <topic>~/shipping_box_visual_toggle</topic>
          </plugin>
        </visual>
        <visual name='closed_box'>
          <geometry>
            <mesh>
              <scale>1.1 1.8 0.25</scale>
              <uri>model://closed_box_ariac/meshes/closed_box.obj</uri>
            </mesh>
          </geometry>
          <plugin name='toggle' filename='libToggleVisualPlugin.so'>
            <initially_visible>0</initially_visible>
            <topic>~/shipping_box_visual_toggle</topic>
          </plugin>
        </visual>
        <self_collide>0</self_collide>
        <enable_wind>0</enable_wind>
        <kinematic>0</kinematic>
      </link>
      <pose frame=''>0.619086 0.071574 0 0 -0 0</pose>
    </model>
    <model name='visp_marker_100mm'>
      <static>1</static>
      <link name='link'>
        <visual name='visual'>
          <geometry>
            <mesh>
              <uri>model://visp_marker_100mm/meshes/visp_marker_100mm.dae</uri>
              <scale>1.125 1.125 1.125</scale>
            </mesh>
          </geometry>
        </visual>
        <self_collide>0</self_collide>
        <enable_wind>0</enable_wind>
        <kinematic>0</kinematic>
      </link>
      <pose frame=''>0.383464 0.165193 0 0 -0 0</pose>
    </model>
    <model name='drone_with_box'>
      <static>1</static>
      <link name='drone::link'>
        <pose frame=''>0 0 0 0 0 -1.5707</pose>
        <collision name='collision'>
          <geometry>
            <mesh>
              <scale>1.3 1.3 1</scale>
              <uri>model://drone_ariac/meshes/Drone.dae</uri>
            </mesh>
          </geometry>
          <max_contacts>10</max_contacts>
          <surface>
            <contact>
              <ode/>
            </contact>
            <bounce/>
            <friction>
              <torsional>
                <ode/>
              </torsional>
              <ode/>
            </friction>
          </surface>
        </collision>
        <visual name='visual'>
          <geometry>
            <mesh>
              <scale>1.3 1.3 1</scale>
              <uri>model://drone_ariac/meshes/Drone.dae</uri>
            </mesh>
          </geometry>
        </visual>
        <self_collide>0</self_collide>
        <enable_wind>0</enable_wind>
        <kinematic>0</kinematic>
      </link>
      <static>1</static>
      <link name='box_link'>
        <visual name='box_visual'>
          <pose frame=''>0 0 -0.13 0 -0 1.5707</pose>
          <geometry>
            <mesh>
              <scale>1.1 1.8 0.25</scale>
              <uri>model://closed_box_ariac/meshes/closed_box.obj</uri>
            </mesh>
          </geometry>
          <plugin name='toggle' filename='libToggleVisualPlugin.so'>
            <initially_visible>0</initially_visible>
            <topic>~/drone_box_visual_toggle</topic>
          </plugin>
        </visual>
        <self_collide>0</self_collide>
        <enable_wind>0</enable_wind>
        <kinematic>0</kinematic>
      </link>
      <pose frame=''>0.549307 3.51078 0 0 -0 0</pose>
    </model>
    <model name='drone_with_box_clone'>
      <static>1</static>
      <link name='drone::link'>
        <pose frame=''>0 0 0 0 0 -1.5707</pose>
        <collision name='collision'>
          <geometry>
            <mesh>
              <scale>1.3 1.3 1</scale>
              <uri>model://drone_ariac/meshes/Drone.dae</uri>
            </mesh>
          </geometry>
          <max_contacts>10</max_contacts>
          <surface>
            <contact>
              <ode/>
            </contact>
            <bounce/>
            <friction>
              <torsional>
                <ode/>
              </torsional>
              <ode/>
            </friction>
          </surface>
        </collision>
        <visual name='visual'>
          <geometry>
            <mesh>
              <scale>1.3 1.3 1</scale>
              <uri>model://drone_ariac/meshes/Drone.dae</uri>
            </mesh>
          </geometry>
        </visual>
        <self_collide>0</self_collide>
        <enable_wind>0</enable_wind>
        <kinematic>0</kinematic>
      </link>
      <static>1</static>
      <link name='box_link'>
        <visual name='box_visual'>
          <pose frame=''>0 0 -0.13 0 -0 1.5707</pose>
          <geometry>
            <mesh>
              <scale>1.1 1.8 0.25</scale>
              <uri>model://closed_box_ariac/meshes/closed_box.obj</uri>
            </mesh>
          </geometry>
          <plugin name='toggle' filename='libToggleVisualPlugin.so'>
            <initially_visible>0</initially_visible>
            <topic>~/drone_box_visual_toggle</topic>
          </plugin>
        </visual>
        <self_collide>0</self_collide>
        <enable_wind>0</enable_wind>
        <kinematic>0</kinematic>
      </link>
      <pose frame=''>0.58877 -5.93038 0 0 -0 0</pose>
    </model>
    <model name='lrmate200id7l'>
      <link name='base_link'>
        <pose frame=''>0 0 0 0 -0 0</pose>
        <inertial>
          <pose frame=''>0.014288 1e-06 0.122264 0 -0 0</pose>
          <mass>10.7335</mass>
          <inertia>
            <ixx>0.09659</ixx>
            <ixy>-5e-06</ixy>
            <ixz>-0.003803</ixz>
            <iyy>0.087591</iyy>
            <iyz>-1e-06</iyz>
            <izz>0.081632</izz>
          </inertia>
        </inertial>
        <collision name='base_link_collision'>
          <pose frame=''>0 0 0 0 -0 0</pose>
          <geometry>
            <mesh>
              <scale>1 1 1</scale>
              <uri>/home/atas/catkin_ws/install/share/fanuc_lrmate200id_support/meshes/lrmate200id/collision/base_link.stl</uri>
            </mesh>
          </geometry>
          <surface>
            <contact>
              <ode/>
            </contact>
            <friction>
              <ode/>
              <torsional>
                <ode/>
              </torsional>
            </friction>
            <bounce/>
          </surface>
          <max_contacts>10</max_contacts>
        </collision>
        <visual name='base_link_visual'>
          <pose frame=''>0 0 0 0 -0 0</pose>
          <geometry>
            <mesh>
              <scale>1 1 1</scale>
              <uri>/home/atas/catkin_ws/install/share/fanuc_lrmate200id_support/meshes/lrmate200id/visual/base_link.stl</uri>
            </mesh>
          </geometry>
          <material>
            <script>
              <name>Gazebo/Yellow</name>
              <uri>file://media/materials/scripts/gazebo.material</uri>
            </script>
          </material>
        </visual>
        <gravity>0</gravity>
        <velocity_decay/>
        <self_collide>0</self_collide>
        <enable_wind>0</enable_wind>
        <kinematic>0</kinematic>
      </link>
      <joint name='world-base_link-fixed' type='fixed'>
        <child>base_link</child>
        <parent>world</parent>
      </joint>
      <link name='link_1'>
        <pose frame=''>0 0 0.33 0 -0 0</pose>
        <inertial>
          <pose frame=''>0.019143 0.024764 -0.064596 0 -0 0</pose>
          <mass>16.9346</mass>
          <inertia>
            <ixx>0.222318</ixx>
            <ixy>0.016499</ixy>
            <ixz>0.023794</ixz>
            <iyy>0.208959</iyy>
            <iyz>0.031663</iyz>
            <izz>0.157081</izz>
          </inertia>
        </inertial>
        <collision name='link_1_collision'>
          <pose frame=''>0 0 0 0 -0 0</pose>
          <geometry>
            <mesh>
              <scale>1 1 1</scale>
              <uri>/home/atas/catkin_ws/install/share/fanuc_lrmate200id_support/meshes/lrmate200id/collision/link_1.stl</uri>
            </mesh>
          </geometry>
          <surface>
            <contact>
              <ode/>
            </contact>
            <friction>
              <ode/>
              <torsional>
                <ode/>
              </torsional>
            </friction>
            <bounce/>
          </surface>
          <max_contacts>10</max_contacts>
        </collision>
        <visual name='link_1_visual'>
          <pose frame=''>0 0 0 0 -0 0</pose>
          <geometry>
            <mesh>
              <scale>1 1 1</scale>
              <uri>/home/atas/catkin_ws/install/share/fanuc_lrmate200id_support/meshes/lrmate200id/visual/link_1.stl</uri>
            </mesh>
          </geometry>
          <material>
            <script>
              <name>Gazebo/Yellow</name>
              <uri>file://media/materials/scripts/gazebo.material</uri>
            </script>
          </material>
        </visual>
        <gravity>0</gravity>
        <velocity_decay/>
        <self_collide>0</self_collide>
        <enable_wind>0</enable_wind>
        <kinematic>0</kinematic>
      </link>
      <joint name='joint_1' type='revolute'>
        <child>link_1</child>
        <parent>base_link</parent>
        <axis>
          <xyz>0 0 1</xyz>
          <limit>
            <lower>-2.965</lower>
            <upper>2.965</upper>
            <effort>0</effort>
            <velocity>7.85</velocity>
          </limit>
          <dynamics>
            <spring_reference>0</spring_reference>
            <spring_stiffness>0</spring_stiffness>
          </dynamics>
          <use_parent_model_frame>1</use_parent_model_frame>
        </axis>
      </joint>
      <link name='link_2'>
        <pose frame=''>0.05 0 0.33 0 -0 0</pose>
        <inertial>
          <pose frame=''>-8e-06 0.221181 0.173052 0 -0 0</pose>
          <mass>12.9871</mass>
          <inertia>
            <ixx>0.425299</ixx>
            <ixy>5e-06</ixy>
            <ixz>-4e-06</ixz>
            <iyy>0.452311</iyy>
            <iyz>-0.00292</iyz>
            <izz>0.054493</izz>
          </inertia>
        </inertial>
        <collision name='link_2_collision'>
          <pose frame=''>0 0 0 0 -0 0</pose>
          <geometry>
            <mesh>
              <scale>0.001 0.001 0.001</scale>
              <uri>/home/atas/catkin_ws/install/share/fanuc_lrmate200id_support/meshes/lrmate200id7l/collision/link_2.stl</uri>
            </mesh>
          </geometry>
          <surface>
            <contact>
              <ode/>
            </contact>
            <friction>
              <ode/>
              <torsional>
                <ode/>
              </torsional>
            </friction>
            <bounce/>
          </surface>
          <max_contacts>10</max_contacts>
        </collision>
        <visual name='link_2_visual'>
          <pose frame=''>0 0 0 0 -0 0</pose>
          <geometry>
            <mesh>
              <scale>0.001 0.001 0.001</scale>
              <uri>/home/atas/catkin_ws/install/share/fanuc_lrmate200id_support/meshes/lrmate200id7l/visual/link_2.stl</uri>
            </mesh>
          </geometry>
          <material>
            <script>
              <name>Gazebo/Yellow</name>
              <uri>file://media/materials/scripts/gazebo.material</uri>
            </script>
          </material>
        </visual>
        <gravity>0</gravity>
        <velocity_decay/>
        <self_collide>0</self_collide>
        <enable_wind>0</enable_wind>
        <kinematic>0</kinematic>
      </link>
      <joint name='joint_2' type='revolute'>
        <child>link_2</child>
        <parent>link_1</parent>
        <axis>
          <xyz>0 1 0</xyz>
          <limit>
            <lower>-1.74533</lower>
            <upper>2.53073</upper>
            <effort>0</effort>
            <velocity>6.63</velocity>
          </limit>
          <dynamics>
            <spring_reference>0</spring_reference>
            <spring_stiffness>0</spring_stiffness>
          </dynamics>
          <use_parent_model_frame>1</use_parent_model_frame>
        </axis>
      </joint>
      <link name='link_3'>
        <pose frame=''>0.05 0 0.77 0 -0 0</pose>
        <inertial>
          <pose frame=''>2e-06 0.065008 0.003572 0 -0 0</pose>
          <mass>7.50151</mass>
          <inertia>
            <ixx>0.058902</ixx>
            <ixy>0</ixy>
            <ixz>1e-06</ixz>
            <iyy>0.056884</iyy>
            <iyz>-0.003672</iyz>
            <izz>0.034271</izz>
          </inertia>
        </inertial>
        <collision name='link_3_collision'>
          <pose frame=''>0 0 0 0 -0 0</pose>
          <geometry>
            <mesh>
              <scale>1 1 1</scale>
              <uri>/home/atas/catkin_ws/install/share/fanuc_lrmate200id_support/meshes/lrmate200id/collision/link_3.stl</uri>
            </mesh>
          </geometry>
          <surface>
            <contact>
              <ode/>
            </contact>
            <friction>
              <ode/>
              <torsional>
                <ode/>
              </torsional>
            </friction>
            <bounce/>
          </surface>
          <max_contacts>10</max_contacts>
        </collision>
        <visual name='link_3_visual'>
          <pose frame=''>0 0 0 0 -0 0</pose>
          <geometry>
            <mesh>
              <scale>1 1 1</scale>
              <uri>/home/atas/catkin_ws/install/share/fanuc_lrmate200id_support/meshes/lrmate200id/visual/link_3.stl</uri>
            </mesh>
          </geometry>
          <material>
            <script>
              <name>Gazebo/Yellow</name>
              <uri>file://media/materials/scripts/gazebo.material</uri>
            </script>
          </material>
        </visual>
        <gravity>0</gravity>
        <velocity_decay/>
        <self_collide>0</self_collide>
        <enable_wind>0</enable_wind>
        <kinematic>0</kinematic>
      </link>
      <joint name='joint_3' type='revolute'>
        <child>link_3</child>
        <parent>link_2</parent>
        <axis>
          <xyz>0 -1 0</xyz>
          <limit>
            <lower>-2.45097</lower>
            <upper>4.88692</upper>
            <effort>0</effort>
            <velocity>9.08</velocity>
          </limit>
          <dynamics>
            <spring_reference>0</spring_reference>
            <spring_stiffness>0</spring_stiffness>
          </dynamics>
          <use_parent_model_frame>1</use_parent_model_frame>
        </axis>
      </joint>
      <link name='link_4'>
        <pose frame=''>0.05 0 0.805 0 -0 0</pose>
        <inertial>
          <pose frame=''>-0.002488 0.049988 0.296156 0 -0 0</pose>
          <mass>4.54015</mass>
          <inertia>
            <ixx>0.043246</ixx>
            <ixy>3e-06</ixy>
            <ixz>-0.000683</ixz>
            <iyy>0.038394</iyy>
            <iyz>-4e-06</iyz>
            <izz>0.014525</izz>
          </inertia>
        </inertial>
        <collision name='link_4_collision'>
          <pose frame=''>0 0 0 0 -0 0</pose>
          <geometry>
            <mesh>
              <scale>0.001 0.001 0.001</scale>
              <uri>/home/atas/catkin_ws/install/share/fanuc_lrmate200id_support/meshes/lrmate200id7l/collision/link_4.stl</uri>
            </mesh>
          </geometry>
          <surface>
            <contact>
              <ode/>
            </contact>
            <friction>
              <ode/>
              <torsional>
                <ode/>
              </torsional>
            </friction>
            <bounce/>
          </surface>
          <max_contacts>10</max_contacts>
        </collision>
        <visual name='link_4_visual'>
          <pose frame=''>0 0 0 0 -0 0</pose>
          <geometry>
            <mesh>
              <scale>0.001 0.001 0.001</scale>
              <uri>/home/atas/catkin_ws/install/share/fanuc_lrmate200id_support/meshes/lrmate200id7l/visual/link_4.stl</uri>
            </mesh>
          </geometry>
          <material>
            <script>
              <name>Gazebo/Yellow</name>
              <uri>file://media/materials/scripts/gazebo.material</uri>
            </script>
          </material>
        </visual>
        <gravity>0</gravity>
        <velocity_decay/>
        <self_collide>0</self_collide>
        <enable_wind>0</enable_wind>
        <kinematic>0</kinematic>
      </link>
      <joint name='joint_4' type='revolute'>
        <child>link_4</child>
        <parent>link_3</parent>
        <axis>
          <xyz>-1 0 0</xyz>
          <limit>
            <lower>-3.315</lower>
            <upper>3.315</upper>
            <effort>0</effort>
            <velocity>9.6</velocity>
          </limit>
          <dynamics>
            <spring_reference>0</spring_reference>
            <spring_stiffness>0</spring_stiffness>
          </dynamics>
          <use_parent_model_frame>1</use_parent_model_frame>
        </axis>
      </joint>
      <link name='link_5'>
        <pose frame=''>0.47 0 0.805 0 -0 0</pose>
        <inertial>
          <pose frame=''>0 0.049931 0.222823 0 -0 0</pose>
          <mass>0.56876</mass>
          <inertia>
            <ixx>0.001084</ixx>
            <ixy>0</ixy>
            <ixz>0</ixz>
            <iyy>0.001123</iyy>
            <iyz>1e-06</iyz>
            <izz>0.000383</izz>
          </inertia>
        </inertial>
        <collision name='link_5_collision'>
          <pose frame=''>0 0 0 0 -0 0</pose>
          <geometry>
            <mesh>
              <scale>1 1 1</scale>
              <uri>/home/atas/catkin_ws/install/share/fanuc_lrmate200id_support/meshes/lrmate200id/collision/link_5.stl</uri>
            </mesh>
          </geometry>
          <surface>
            <contact>
              <ode/>
            </contact>
            <friction>
              <ode/>
              <torsional>
                <ode/>
              </torsional>
            </friction>
            <bounce/>
          </surface>
          <max_contacts>10</max_contacts>
        </collision>
        <visual name='link_5_visual'>
          <pose frame=''>0 0 0 0 -0 0</pose>
          <geometry>
            <mesh>
              <scale>1 1 1</scale>
              <uri>/home/atas/catkin_ws/install/share/fanuc_lrmate200id_support/meshes/lrmate200id/visual/link_5.stl</uri>
            </mesh>
          </geometry>
          <material>
            <script>
              <name>Gazebo/Grey</name>
              <uri>file://media/materials/scripts/gazebo.material</uri>
            </script>
          </material>
        </visual>
        <gravity>0</gravity>
        <velocity_decay/>
        <self_collide>0</self_collide>
        <enable_wind>0</enable_wind>
        <kinematic>0</kinematic>
      </link>
      <joint name='joint_5' type='revolute'>
        <child>link_5</child>
        <parent>link_4</parent>
        <axis>
          <xyz>0 -1 0</xyz>
          <limit>
            <lower>-2.18</lower>
            <upper>2.18</upper>
            <effort>0</effort>
            <velocity>9.51</velocity>
          </limit>
          <dynamics>
            <spring_reference>0</spring_reference>
            <spring_stiffness>0</spring_stiffness>
          </dynamics>
          <use_parent_model_frame>1</use_parent_model_frame>
        </axis>
      </joint>
      <link name='link_6'>
        <pose frame=''>0.55 0 0.805 0 -0 0</pose>
        <inertial>
          <pose frame=''>-0.000184 0.042069 0.012934 0 -0 0</pose>
          <mass>0.04098</mass>
          <inertia>
            <ixx>0.00394816</ixx>
            <ixy>5.97034e-08</ixy>
            <ixz>-1.44745e-07</ixz>
            <iyy>0.000556874</iyy>
            <iyz>1.93589e-05</iyz>
            <izz>0.00390924</izz>
          </inertia>
        </inertial>
        <collision name='link_6_collision'>
          <pose frame=''>0 0 0 0 -0 0</pose>
          <geometry>
            <mesh>
              <scale>1 1 1</scale>
              <uri>/home/atas/catkin_ws/install/share/fanuc_lrmate200id_support/meshes/lrmate200id/collision/link_6.stl</uri>
            </mesh>
          </geometry>
          <surface>
            <contact>
              <ode/>
            </contact>
            <friction>
              <ode/>
              <torsional>
                <ode/>
              </torsional>
            </friction>
            <bounce/>
          </surface>
          <max_contacts>10</max_contacts>
        </collision>
        <collision name='link_6_fixed_joint_lump__camera_link_collision_1'>
          <pose frame=''>0 0 0.0725 0 -0 0</pose>
          <geometry>
            <box>
              <size>0.02505 0.09 0.025</size>
            </box>
          </geometry>
          <surface>
            <contact>
              <ode>
                <kp>1e+13</kp>
                <kd>1</kd>
              </ode>
            </contact>
            <friction>
              <ode>
                <mu2>1</mu2>
                <fdir1>0 0 0</fdir1>
              </ode>
              <torsional>
                <ode/>
              </torsional>
            </friction>
            <bounce/>
          </surface>
          <max_contacts>10</max_contacts>
        </collision>
        <visual name='link_6_visual'>
          <pose frame=''>0 0 0 0 -0 0</pose>
          <geometry>
            <mesh>
              <scale>1 1 1</scale>
              <uri>/home/atas/catkin_ws/install/share/fanuc_lrmate200id_support/meshes/lrmate200id/visual/link_6.stl</uri>
            </mesh>
          </geometry>
          <material>
            <script>
              <name>Gazebo/Grey</name>
              <uri>file://media/materials/scripts/gazebo.material</uri>
            </script>
          </material>
        </visual>
        <visual name='link_6_fixed_joint_lump__camera_link_visual_1'>
          <pose frame=''>0.0149 0 0.0725 1.5708 -0 1.5708</pose>
          <geometry>
            <mesh>
              <scale>1 1 1</scale>
              <uri>/home/atas/catkin_ws/install/share/fanuc_lrmate200id_gazebo/meshes/d435.dae</uri>
            </mesh>
          </geometry>
          <material>
            <script>
              <uri>__default__</uri>
              <name>__default__</name>
            </script>
          </material>
        </visual>
        <velocity_decay/>
        <gravity>0</gravity>
        <velocity_decay/>
        <self_collide>0</self_collide>
        <enable_wind>0</enable_wind>
        <kinematic>0</kinematic>
        <gravity>0</gravity>
        <sensor name='cameracolor' type='camera'>
          <camera name='camera'>
            <horizontal_fov>1.48702</horizontal_fov>
            <image>
              <width>1280</width>
              <height>720</height>
              <format>RGB_INT8</format>
            </image>
            <clip>
              <near>0.1</near>
              <far>100</far>
            </clip>
            <noise>
              <type>gaussian</type>
              <mean>0</mean>
              <stddev>0.007</stddev>
            </noise>
          </camera>
          <always_on>1</always_on>
          <update_rate>30</update_rate>
          <visualize>1</visualize>
          <pose frame=''>0 0.0175 0.0725 0 -0 0</pose>
        </sensor>
        <sensor name='cameraired1' type='camera'>
          <camera name='camera'>
            <horizontal_fov>1.48702</horizontal_fov>
            <image>
              <width>1280</width>
              <height>720</height>
              <format>L_INT8</format>
            </image>
            <clip>
              <near>0.1</near>
              <far>100</far>
            </clip>
            <noise>
              <type>gaussian</type>
              <mean>0</mean>
              <stddev>0.05</stddev>
            </noise>
          </camera>
          <always_on>1</always_on>
          <update_rate>1</update_rate>
          <visualize>0</visualize>
          <pose frame=''>0 0.0175 0.0725 0 -0 0</pose>
        </sensor>
        <sensor name='cameraired2' type='camera'>
          <camera name='camera'>
            <horizontal_fov>1.48702</horizontal_fov>
            <image>
              <width>1280</width>
              <height>720</height>
              <format>L_INT8</format>
            </image>
            <clip>
              <near>0.1</near>
              <far>100</far>
            </clip>
            <noise>
              <type>gaussian</type>
              <mean>0</mean>
              <stddev>0.05</stddev>
            </noise>
          </camera>
          <always_on>1</always_on>
          <update_rate>1</update_rate>
          <visualize>0</visualize>
          <pose frame=''>0 0.0175 0.0725 0 -0 0</pose>
        </sensor>
        <sensor name='cameradepth' type='depth'>
          <camera name='camera'>
            <horizontal_fov>1.48702</horizontal_fov>
            <image>
              <width>1280</width>
              <height>720</height>
            </image>
            <clip>
              <near>0.1</near>
              <far>100</far>
            </clip>
            <noise>
              <type>gaussian</type>
              <mean>0</mean>
              <stddev>0.1</stddev>
            </noise>
          </camera>
          <always_on>1</always_on>
          <update_rate>30</update_rate>
          <visualize>0</visualize>
          <pose frame=''>0 0.0175 0.0725 0 -0 0</pose>
        </sensor>
      </link>
      <joint name='joint_6' type='revolute'>
        <child>link_6</child>
        <parent>link_5</parent>
        <axis>
          <xyz>-1 0 0</xyz>
          <limit>
            <lower>-6.285</lower>
            <upper>6.285</upper>
            <effort>0</effort>
            <velocity>17.45</velocity>
          </limit>
          <dynamics>
            <spring_reference>0</spring_reference>
            <spring_stiffness>0</spring_stiffness>
          </dynamics>
          <use_parent_model_frame>1</use_parent_model_frame>
        </axis>
      </joint>
      <plugin name='gazebo_ros_control' filename='libgazebo_ros_control.so'>
        <robotNamespace>/</robotNamespace>
        <robotSimType>gazebo_ros_control/DefaultRobotHWSim</robotSimType>
      </plugin>
      <static>0</static>
      <plugin name='camera' filename='libfanuc_lrmate200id_gazebo_realsense_gazebo_plugin.so'>
        <prefix>camera</prefix>
        <depthUpdateRate>30.0</depthUpdateRate>
        <colorUpdateRate>30.0</colorUpdateRate>
        <infraredUpdateRate>1.0</infraredUpdateRate>
        <depthTopicName>aligned_depth_to_color/image_raw</depthTopicName>
        <depthCameraInfoTopicName>depth/camera_info</depthCameraInfoTopicName>
        <colorTopicName>color/image_raw</colorTopicName>
        <colorCameraInfoTopicName>color/camera_info</colorCameraInfoTopicName>
        <infrared1TopicName>infra1/image_raw</infrared1TopicName>
        <infrared1CameraInfoTopicName>infra1/camera_info</infrared1CameraInfoTopicName>
        <infrared2TopicName>infra2/image_raw</infrared2TopicName>
        <infrared2CameraInfoTopicName>infra2/camera_info</infrared2CameraInfoTopicName>
        <colorOpticalframeName>camera_color_optical_frame</colorOpticalframeName>
        <depthOpticalframeName>camera_depth_optical_frame</depthOpticalframeName>
        <infrared1OpticalframeName>camera_left_ir_optical_frame</infrared1OpticalframeName>
        <infrared2OpticalframeName>camera_right_ir_optical_frame</infrared2OpticalframeName>
        <rangeMinDepth>0.3</rangeMinDepth>
        <rangeMaxDepth>3.0</rangeMaxDepth>
        <pointCloud>1</pointCloud>
        <pointCloudTopicName>depth/color/points</pointCloudTopicName>
        <pointCloudCutoff>0.3</pointCloudCutoff>
        <robotNamespace>/</robotNamespace>
      </plugin>
      <pose frame=''>0 0 0 0 -0 0</pose>
    </model>
  </world>
</sdf>
